Workbook

Sheet cloudSense
A1: record_id | B1: date | C1: service_name | D1: region | E1: cpu_usage_percent | F1: storage_gb | G1: allocated_cost | H1: actual_used_cost | I1: resource_status | J1: service_clean | K1: region_clean | L1: status_clean | M1: Column1 | N1: waste_cost | O1: waste_percent
A2: 1 | B2: 45658 | C2: EC2 | D2: us-east | E2: 23 | F2: 120 | G2: 500 | H2: 210 | I2: Idle | J2: =UPPER(TRIM(cloudSense[[#This Row],[service_name]])) -> EC2 | K2: =LOWER(TRIM(cloudSense[[#This Row],[region]])) -> us-east | L2: =PROPER(TRIM(cloudSense[[#This Row],[resource_status]])) -> Idle | N2: =cloudSense[[#This Row],[allocated_cost]]-cloudSense[[#This Row],[actual_used_cost]] -> 290 | O2: =(cloudSense[[#This Row],[allocated_cost]]-cloudSense[[#This Row],[actual_used_cost]])/cloudSense[[#This Row],[allocated_cost]]*100 -> 58
A3: 2 | B3: 45658 | C3: S3 | D3: us-west | E3: 78 | F3: 450 | G3: 700 | H3: 690 | I3: Active | J3: =UPPER(TRIM(cloudSense[[#This Row],[service_name]])) -> S3 | K3: =LOWER(TRIM(cloudSense[[#This Row],[region]])) -> us-west | L3: =PROPER(TRIM(cloudSense[[#This Row],[resource_status]])) -> Active | N3: =cloudSense[[#This Row],[allocated_cost]]-cloudSense[[#This Row],[actual_used_cost]] -> 10 | O3: =(cloudSense[[#This Row],[allocated_cost]]-cloudSense[[#This Row],[actual_used_cost]])/cloudSense[[#This Row],[allocated_cost]]*100 -> 1.4285714
A4: 3 | B4: 45659 | C4: ec2 | D4: us-east | E4: 12 | F4: 90 | G4: 500 | H4: 120 | I4: idle | J4: =UPPER(TRIM(cloudSense[[#This Row],[service_name]])) -> EC2 | K4: =LOWER(TRIM(cloudSense[[#This Row],[region]])) -> us-east | L4: =PROPER(TRIM(cloudSense[[#This Row],[resource_status]])) -> Idle | N4: =cloudSense[[#This Row],[allocated_cost]]-cloudSense[[#This Row],[actual_used_cost]] -> 380 | O4: =(cloudSense[[#This Row],[allocated_cost]]-cloudSense[[#This Row],[actual_used_cost]])/cloudSense[[#This Row],[allocated_cost]]*100 -> 76
A5: 4 | B5: 45659 | C5: RDS | D5: eu-central | E5: 65 | F5: 300 | G5: 600 | H5: 580 | I5: Active | J5: =UPPER(TRIM(cloudSense[[#This Row],[service_name]])) -> RDS | K5: =LOWER(TRIM(cloudSense[[#This Row],[region]])) -> eu-central | L5: =PROPER(TRIM(cloudSense[[#This Row],[resource_status]])) -> Active | N5: =cloudSense[[#This Row],[allocated_cost]]-cloudSense[[#This Row],[actual_used_cost]] -> 20 | O5: =(cloudSense[[#This Row],[allocated_cost]]-cloudSense[[#This Row],[actual_used_cost]])/cloudSense[[#This Row],[allocated_cost]]*100 -> 3.3333333
A6: 5 | B6: 45660 | C6: Lambda | D6: asia-south | E6: 5 | F6: 20 | G6: 200 | H6: 50 | I6: Idle | J6: =UPPER(TRIM(cloudSense[[#This Row],[service_name]])) -> LAMBDA | K6: =LOWER(TRIM(cloudSense[[#This Row],[region]])) -> asia-south | L6: =PROPER(TRIM(cloudSense[[#This Row],[resource_status]])) -> Idle | N6: =cloudSense[[#This Row],[allocated_cost]]-cloudSense[[#This Row],[actual_used_cost]] -> 150 | O6: =(cloudSense[[#This Row],[allocated_cost]]-cloudSense[[#This Row],[actual_used_cost]])/cloudSense[[#This Row],[allocated_cost]]*100 -> 75
A7: 6 | B7: 45660 | C7: S3 | D7: us-west | F7: 400 | G7: 700 | H7: 650 | I7: Active | J7: =UPPER(TRIM(cloudSense[[#This Row],[service_name]])) -> S3 | K7: =LOWER(TRIM(cloudSense[[#This Row],[region]])) -> us-west | L7: =PROPER(TRIM(cloudSense[[#This Row],[resource_status]])) -> Active | N7: =cloudSense[[#This Row],[allocated_cost]]-cloudSense[[#This Row],[actual_used_cost]] -> 50 | O7: =(cloudSense[[#This Row],[allocated_cost]]-cloudSense[[#This Row],[actual_used_cost]])/cloudSense[[#This Row],[allocated_cost]]*100 -> 7.1428571
A8: 7 | B8: 45661 | C8: EC2 | D8: us-east | E8: 33 | F8: 150 | G8: 500 | H8: 300 | I8: Active | J8: =UPPER(TRIM(cloudSense[[#This Row],[service_name]])) -> EC2 | K8: =LOWER(TRIM(cloudSense[[#This Row],[region]])) -> us-east | L8: =PROPER(TRIM(cloudSense[[#This Row],[resource_status]])) -> Active | N8: =cloudSense[[#This Row],[allocated_cost]]-cloudSense[[#This Row],[actual_used_cost]] -> 200 | O8: =(cloudSense[[#This Row],[allocated_cost]]-cloudSense[[#This Row],[actual_used_cost]])/cloudSense[[#This Row],[allocated_cost]]*100 -> 40
A9: 8 | B9: 45661 | C9: RDS | D9: EU-CENTRAL | E9: 18 | F9: 200 | G9: 600 | H9: 150 | I9: Idle | J9: =UPPER(TRIM(cloudSense[[#This Row],[service_name]])) -> RDS | K9: =LOWER(TRIM(cloudSense[[#This Row],[region]])) -> eu-central | L9: =PROPER(TRIM(cloudSense[[#This Row],[resource_status]])) -> Idle | N9: =cloudSense[[#This Row],[allocated_cost]]-cloudSense[[#This Row],[actual_used_cost]] -> 450 | O9: =(cloudSense[[#This Row],[allocated_cost]]-cloudSense[[#This Row],[actual_used_cost]])/cloudSense[[#This Row],[allocated_cost]]*100 -> 75
A10: 9 | B10: 45662 | C10: EC2 | D10: us-east | E10: 90 | F10: 250 | G10: 500 | H10: 480 | I10: Active | J10: =UPPER(TRIM(cloudSense[[#This Row],[service_name]])) -> EC2 | K10: =LOWER(TRIM(cloudSense[[#This Row],[region]])) -> us-east | L10: =PROPER(TRIM(cloudSense[[#This Row],[resource_status]])) -> Active | N10: =cloudSense[[#This Row],[allocated_cost]]-cloudSense[[#This Row],[actual_used_cost]] -> 20 | O10: =(cloudSense[[#This Row],[allocated_cost]]-cloudSense[[#This Row],[actual_used_cost]])/cloudSense[[#This Row],[allocated_cost]]*100 -> 4
A11: 10 | B11: 45662 | C11: S3 | D11: us-west | E11: 45 | F11: 500 | G11: 700 | H11: 400 | I11: Active | J11: =UPPER(TRIM(cloudSense[[#This Row],[service_name]])) -> S3 | K11: =LOWER(TRIM(cloudSense[[#This Row],[region]])) -> us-west | L11: =PROPER(TRIM(cloudSense[[#This Row],[resource_status]])) -> Active | N11: =cloudSense[[#This Row],[allocated_cost]]-cloudSense[[#This Row],[actual_used_cost]] -> 300 | O11: =(cloudSense[[#This Row],[allocated_cost]]-cloudSense[[#This Row],[actual_used_cost]])/cloudSense[[#This Row],[allocated_cost]]*100 -> 42.857143
A12: 11 | B12: 45663 | C12: ec2 | D12: us-east | E12: 8 | F12: 80 | G12: 500 | H12: 60 | I12: Idle | J12: =UPPER(TRIM(cloudSense[[#This Row],[service_name]])) -> EC2 | K12: =LOWER(TRIM(cloudSense[[#This Row],[region]])) -> us-east | L12: =PROPER(TRIM(cloudSense[[#This Row],[resource_status]])) -> Idle | N12: =cloudSense[[#This Row],[allocated_cost]]-cloudSense[[#This Row],[actual_used_cost]] -> 440 | O12: =(cloudSense[[#This Row],[allocated_cost]]-cloudSense[[#This Row],[actual_used_cost]])/cloudSense[[#This Row],[allocated_cost]]*100 -> 88
A13: 12 | B13: 45663 | C13: RDS | D13: asia-south | E13: 72 | F13: 350 | G13: 600 | H13: 590 | I13: Active | J13: =UPPER(TRIM(cloudSense[[#This Row],[service_name]])) -> RDS | K13: =LOWER(TRIM(cloudSense[[#This Row],[region]])) -> asia-south | L13: =PROPER(TRIM(cloudSense[[#This Row],[resource_status]])) -> Active | N13: =cloudSense[[#This Row],[allocated_cost]]-cloudSense[[#This Row],[actual_used_cost]] -> 10 | O13: =(cloudSense[[#This Row],[allocated_cost]]-cloudSense[[#This Row],[actual_used_cost]])/cloudSense[[#This Row],[allocated_cost]]*100 -> 1.6666667
A14: 13 | B14: 45664 | C14: Lambda | D14: us-west | E14: 3 | F14: 15 | G14: 200 | H14: 40 | I14: Idle | J14: =UPPER(TRIM(cloudSense[[#This Row],[service_name]])) -> LAMBDA | K14: =LOWER(TRIM(cloudSense[[#This Row],[region]])) -> us-west | L14: =PROPER(TRIM(cloudSense[[#This Row],[resource_status]])) -> Idle | N14: =cloudSense[[#This Row],[allocated_cost]]-cloudSense[[#This Row],[actual_used_cost]] -> 160 | O14: =(cloudSense[[#This Row],[allocated_cost]]-cloudSense[[#This Row],[actual_used_cost]])/cloudSense[[#This Row],[allocated_cost]]*100 -> 80
A15: 14 | B15: 45664 | C15: S3 | D15: us-west | E15: 88 | F15: 520 | G15: 700 | H15: 680 | I15: Active | J15: =UPPER(TRIM(cloudSense[[#This Row],[service_name]])) -> S3 | K15: =LOWER(TRIM(cloudSense[[#This Row],[region]])) -> us-west | L15: =PROPER(TRIM(cloudSense[[#This Row],[resource_status]])) -> Active | N15: =cloudSense[[#This Row],[allocated_cost]]-cloudSense[[#This Row],[actual_used_cost]] -> 20 | O15: =(cloudSense[[#This Row],[allocated_cost]]-cloudSense[[#This Row],[actual_used_cost]])/cloudSense[[#This Row],[allocated_cost]]*100 -> 2.8571429
A16: 15 | B16: 45665 | C16: EC2 | D16: us-east | E16: 25 | F16: 140 | G16: 500 | H16: 260 | I16: Active | J16: =UPPER(TRIM(cloudSense[[#This Row],[service_name]])) -> EC2 | K16: =LOWER(TRIM(cloudSense[[#This Row],[region]])) -> us-east | L16: =PROPER(TRIM(cloudSense[[#This Row],[resource_status]])) -> Active | N16: =cloudSense[[#This Row],[allocated_cost]]-cloudSense[[#This Row],[actual_used_cost]] -> 240 | O16: =(cloudSense[[#This Row],[allocated_cost]]-cloudSense[[#This Row],[actual_used_cost]])/cloudSense[[#This Row],[allocated_cost]]*100 -> 48
A17: 16 | B17: 45665 | C17: RDS | D17: eu-central | F17: 280 | G17: 600 | H17: 400 | I17: Idle | J17: =UPPER(TRIM(cloudSense[[#This Row],[service_name]])) -> RDS | K17: =LOWER(TRIM(cloudSense[[#This Row],[region]])) -> eu-central | L17: =PROPER(TRIM(cloudSense[[#This Row],[resource_status]])) -> Idle | N17: =cloudSense[[#This Row],[allocated_cost]]-cloudSense[[#This Row],[actual_used_cost]] -> 200 | O17: =(cloudSense[[#This Row],[allocated_cost]]-cloudSense[[#This Row],[actual_used_cost]])/cloudSense[[#This Row],[allocated_cost]]*100 -> 33.333333
A18: 17 | B18: 45666 | C18: Lambda | D18: asia-south | E18: 6 | F18: 25 | G18: 200 | H18: 55 | I18: Idle | J18: =UPPER(TRIM(cloudSense[[#This Row],[service_name]])) -> LAMBDA | K18: =LOWER(TRIM(cloudSense[[#This Row],[region]])) -> asia-south | L18: =PROPER(TRIM(cloudSense[[#This Row],[resource_status]])) -> Idle | N18: =cloudSense[[#This Row],[allocated_cost]]-cloudSense[[#This Row],[actual_used_cost]] -> 145 | O18: =(cloudSense[[#This Row],[allocated_cost]]-cloudSense[[#This Row],[actual_used_cost]])/cloudSense[[#This Row],[allocated_cost]]*100 -> 72.5
A19: 18 | B19: 45666 | C19: S3 | D19: us-west | E19: 92 | F19: 550 | G19: 700 | H19: 700 | I19: Active | J19: =UPPER(TRIM(cloudSense[[#This Row],[service_name]])) -> S3 | K19: =LOWER(TRIM(cloudSense[[#This Row],[region]])) -> us-west | L19: =PROPER(TRIM(cloudSense[[#This Row],[resource_status]])) -> Active | N19: =cloudSense[[#This Row],[allocated_cost]]-cloudSense[[#This Row],[actual_used_cost]] -> 0 | O19: =(cloudSense[[#This Row],[allocated_cost]]-cloudSense[[#This Row],[actual_used_cost]])/cloudSense[[#This Row],[allocated_cost]]*100 -> 0
A20: 19 | B20: 45667 | C20: ec2 | D20: us-east | E20: 15 | F20: 100 | G20: 500 | H20: 150 | I20: idle | J20: =UPPER(TRIM(cloudSense[[#This Row],[service_name]])) -> EC2 | K20: =LOWER(TRIM(cloudSense[[#This Row],[region]])) -> us-east | L20: =PROPER(TRIM(cloudSense[[#This Row],[resource_status]])) -> Idle | N20: =cloudSense[[#This Row],[allocated_cost]]-cloudSense[[#This Row],[actual_used_cost]] -> 350 | O20: =(cloudSense[[#This Row],[allocated_cost]]-cloudSense[[#This Row],[actual_used_cost]])/cloudSense[[#This Row],[allocated_cost]]*100 -> 70
A21: 20 | B21: 45667 | C21: RDS | D21: EU-CENTRAL | E21: 60 | F21: 310 | G21: 600 | H21: 570 | I21: Active | J21: =UPPER(TRIM(cloudSense[[#This Row],[service_name]])) -> RDS | K21: =LOWER(TRIM(cloudSense[[#This Row],[region]])) -> eu-central | L21: =PROPER(TRIM(cloudSense[[#This Row],[resource_status]])) -> Active | N21: =cloudSense[[#This Row],[allocated_cost]]-cloudSense[[#This Row],[actual_used_cost]] -> 30 | O21: =(cloudSense[[#This Row],[allocated_cost]]-cloudSense[[#This Row],[actual_used_cost]])/cloudSense[[#This Row],[allocated_cost]]*100 -> 5
A22: 21 | B22: 45668 | C22: EC2 | D22: us-east | E22: 30 | F22: 160 | G22: 500 | H22: 280 | I22: Active | J22: =UPPER(TRIM(cloudSense[[#This Row],[service_name]])) -> EC2 | K22: =LOWER(TRIM(cloudSense[[#This Row],[region]])) -> us-east | L22: =PROPER(TRIM(cloudSense[[#This Row],[resource_status]])) -> Active | N22: =cloudSense[[#This Row],[allocated_cost]]-cloudSense[[#This Row],[actual_used_cost]] -> 220 | O22: =(cloudSense[[#This Row],[allocated_cost]]-cloudSense[[#This Row],[actual_used_cost]])/cloudSense[[#This Row],[allocated_cost]]*100 -> 44
A23: 22 | B23: 45668 | C23: S3 | D23: us-west | E23: 70 | F23: 430 | G23: 700 | H23: 620 | I23: Active | J23: =UPPER(TRIM(cloudSense[[#This Row],[service_name]])) -> S3 | K23: =LOWER(TRIM(cloudSense[[#This Row],[region]])) -> us-west | L23: =PROPER(TRIM(cloudSense[[#This Row],[resource_status]])) -> Active | N23: =cloudSense[[#This Row],[allocated_cost]]-cloudSense[[#This Row],[actual_used_cost]] -> 80 | O23: =(cloudSense[[#This Row],[allocated_cost]]-cloudSense[[#This Row],[actual_used_cost]])/cloudSense[[#This Row],[allocated_cost]]*100 -> 11.428571
A24: 23 | B24: 45669 | C24: ec2 | D24: us-east | E24: 10 | F24: 95 | G24: 500 | H24: 100 | I24: Idle | J24: =UPPER(TRIM(cloudSense[[#This Row],[service_name]])) -> EC2 | K24: =LOWER(TRIM(cloudSense[[#This Row],[region]])) -> us-east | L24: =PROPER(TRIM(cloudSense[[#This Row],[resource_status]])) -> Idle | N24: =cloudSense[[#This Row],[allocated_cost]]-cloudSense[[#This Row],[actual_used_cost]] -> 400 | O24: =(cloudSense[[#This Row],[allocated_cost]]-cloudSense[[#This Row],[actual_used_cost]])/cloudSense[[#This Row],[allocated_cost]]*100 -> 80
A25: 24 | B25: 45669 | C25: RDS | D25: eu-central | E25: 55 | F25: 290 | G25: 600 | H25: 500 | I25: Active | J25: =UPPER(TRIM(cloudSense[[#This Row],[service_name]])) -> RDS | K25: =LOWER(TRIM(cloudSense[[#This Row],[region]])) -> eu-central | L25: =PROPER(TRIM(cloudSense[[#This Row],[resource_status]])) -> Active | N25: =cloudSense[[#This Row],[allocated_cost]]-cloudSense[[#This Row],[actual_used_cost]] -> 100 | O25: =(cloudSense[[#This Row],[allocated_cost]]-cloudSense[[#This Row],[actual_used_cost]])/cloudSense[[#This Row],[allocated_cost]]*100 -> 16.666667
A26: 25 | B26: 45670 | C26: Lambda | D26: asia-south | E26: 4 | F26: 18 | G26: 200 | H26: 45 | I26: Idle | J26: =UPPER(TRIM(cloudSense[[#This Row],[service_name]])) -> LAMBDA | K26: =LOWER(TRIM(cloudSense[[#This Row],[region]])) -> asia-south | L26: =PROPER(TRIM(cloudSense[[#This Row],[resource_status]])) -> Idle | N26: =cloudSense[[#This Row],[allocated_cost]]-cloudSense[[#This Row],[actual_used_cost]] -> 155 | O26: =(cloudSense[[#This Row],[allocated_cost]]-cloudSense[[#This Row],[actual_used_cost]])/cloudSense[[#This Row],[allocated_cost]]*100 -> 77.5
A27: 26 | B27: 45670 | C27: S3 | D27: us-west | E27: 80 | F27: 480 | G27: 700 | H27: 650 | I27: Active | J27: =UPPER(TRIM(cloudSense[[#This Row],[service_name]])) -> S3 | K27: =LOWER(TRIM(cloudSense[[#This Row],[region]])) -> us-west | L27: =PROPER(TRIM(cloudSense[[#This Row],[resource_status]])) -> Active | N27: =cloudSense[[#This Row],[allocated_cost]]-cloudSense[[#This Row],[actual_used_cost]] -> 50 | O27: =(cloudSense[[#This Row],[allocated_cost]]-cloudSense[[#This Row],[actual_used_cost]])/cloudSense[[#This Row],[allocated_cost]]*100 -> 7.1428571
A28: 27 | B28: 45671 | C28: EC2 | D28: us-east | E28: 35 | F28: 170 | G28: 500 | H28: 320 | I28: Active | J28: =UPPER(TRIM(cloudSense[[#This Row],[service_name]])) -> EC2 | K28: =LOWER(TRIM(cloudSense[[#This Row],[region]])) -> us-east | L28: =PROPER(TRIM(cloudSense[[#This Row],[resource_status]])) -> Active | N28: =cloudSense[[#This Row],[allocated_cost]]-cloudSense[[#This Row],[actual_used_cost]] -> 180 | O28: =(cloudSense[[#This Row],[allocated_cost]]-cloudSense[[#This Row],[actual_used_cost]])/cloudSense[[#This Row],[allocated_cost]]*100 -> 36
A29: 28 | B29: 45671 | C29: RDS | D29: EU-CENTRAL | E29: 20 | F29: 210 | G29: 600 | H29: 160 | I29: Idle | J29: =UPPER(TRIM(cloudSense[[#This Row],[service_name]])) -> RDS | K29: =LOWER(TRIM(cloudSense[[#This Row],[region]])) -> eu-central | L29: =PROPER(TRIM(cloudSense[[#This Row],[resource_status]])) -> Idle | N29: =cloudSense[[#This Row],[allocated_cost]]-cloudSense[[#This Row],[actual_used_cost]] -> 440 | O29: =(cloudSense[[#This Row],[allocated_cost]]-cloudSense[[#This Row],[actual_used_cost]])/cloudSense[[#This Row],[allocated_cost]]*100 -> 73.333333
... A36: 35 | B36: 45675 | C36: EC2 | D36: us-east | E36: 28 | F36: 145 | G36: 500 | H36: 270 | I36: Active | J36: =UPPER(TRIM(cloudSense[[#This Row],[service_name]])) -> EC2 | K36: =LOWER(TRIM(cloudSense[[#This Row],[region]])) -> us-east | L36: =PROPER(TRIM(cloudSense[[#This Row],[resource_status]])) -> Active | N36: =cloudSense[[#This Row],[allocated_cost]]-cloudSense[[#This Row],[actual_used_cost]] -> 230 | O36: =(cloudSense[[#This Row],[allocated_cost]]-cloudSense[[#This Row],[actual_used_cost]])/cloudSense[[#This Row],[allocated_cost]]*100 -> 46
A37: 36 | B37: 45675 | C37: RDS | D37: eu-central | F37: 275 | G37: 600 | H37: 390 | I37: Idle | J37: =UPPER(TRIM(cloudSense[[#This Row],[service_name]])) -> RDS | K37: =LOWER(TRIM(cloudSense[[#This Row],[region]])) -> eu-central | L37: =PROPER(TRIM(cloudSense[[#This Row],[resource_status]])) -> Idle | N37: =cloudSense[[#This Row],[allocated_cost]]-cloudSense[[#This Row],[actual_used_cost]] -> 210 | O37: =(cloudSense[[#This Row],[allocated_cost]]-cloudSense[[#This Row],[actual_used_cost]])/cloudSense[[#This Row],[allocated_cost]]*100 -> 35
A38: 37 | B38: 45676 | C38: Lambda | D38: asia-south | E38: 7 | F38: 28 | G38: 200 | H38: 60 | I38: Idle | J38: =UPPER(TRIM(cloudSense[[#This Row],[service_name]])) -> LAMBDA | K38: =LOWER(TRIM(cloudSense[[#This Row],[region]])) -> asia-south | L38: =PROPER(TRIM(cloudSense[[#This Row],[resource_status]])) -> Idle | N38: =cloudSense[[#This Row],[allocated_cost]]-cloudSense[[#This Row],[actual_used_cost]] -> 140 | O38: =(cloudSense[[#This Row],[allocated_cost]]-cloudSense[[#This Row],[actual_used_cost]])/cloudSense[[#This Row],[allocated_cost]]*100 -> 70
A39: 38 | B39: 45676 | C39: S3 | D39: us-west | E39: 93 | F39: 560 | G39: 700 | H39: 700 | I39: Active | J39: =UPPER(TRIM(cloudSense[[#This Row],[service_name]])) -> S3 | K39: =LOWER(TRIM(cloudSense[[#This Row],[region]])) -> us-west | L39: =PROPER(TRIM(cloudSense[[#This Row],[resource_status]])) -> Active | N39: =cloudSense[[#This Row],[allocated_cost]]-cloudSense[[#This Row],[actual_used_cost]] -> 0 | O39: =(cloudSense[[#This Row],[allocated_cost]]-cloudSense[[#This Row],[actual_used_cost]])/cloudSense[[#This Row],[allocated_cost]]*100 -> 0
A40: 39 | B40: 45677 | C40: ec2 | D40: us-east | E40: 14 | F40: 105 | G40: 500 | H40: 160 | I40: idle | J40: =UPPER(TRIM(cloudSense[[#This Row],[service_name]])) -> EC2 | K40: =LOWER(TRIM(cloudSense[[#This Row],[region]])) -> us-east | L40: =PROPER(TRIM(cloudSense[[#This Row],[resource_status]])) -> Idle | N40: =cloudSense[[#This Row],[allocated_cost]]-cloudSense[[#This Row],[actual_used_cost]] -> 340 | O40: =(cloudSense[[#This Row],[allocated_cost]]-cloudSense[[#This Row],[actual_used_cost]])/cloudSense[[#This Row],[allocated_cost]]*100 -> 68
A41: 40 | B41: 45677 | C41: RDS | D41: EU-CENTRAL | E41: 62 | F41: 315 | G41: 600 | H41: 575 | I41: Active | J41: =UPPER(TRIM(cloudSense[[#This Row],[service_name]])) -> RDS | K41: =LOWER(TRIM(cloudSense[[#This Row],[region]])) -> eu-central | L41: =PROPER(TRIM(cloudSense[[#This Row],[resource_status]])) -> Active | N41: =cloudSense[[#This Row],[allocated_cost]]-cloudSense[[#This Row],[actual_used_cost]] -> 25 | O41: =(cloudSense[[#This Row],[allocated_cost]]-cloudSense[[#This Row],[actual_used_cost]])/cloudSense[[#This Row],[allocated_cost]]*100 -> 4.1666667
A42: 41 | B42: 45678 | C42: EC2 | D42: us-east | E42: 32 | F42: 165 | G42: 500 | H42: 285 | I42: Active | J42: =UPPER(TRIM(cloudSense[[#This Row],[service_name]])) -> EC2 | K42: =LOWER(TRIM(cloudSense[[#This Row],[region]])) -> us-east | L42: =PROPER(TRIM(cloudSense[[#This Row],[resource_status]])) -> Active | N42: =cloudSense[[#This Row],[allocated_cost]]-cloudSense[[#This Row],[actual_used_cost]] -> 215 | O42: =(cloudSense[[#This Row],[allocated_cost]]-cloudSense[[#This Row],[actual_used_cost]])/cloudSense[[#This Row],[allocated_cost]]*100 -> 43
A43: 42 | B43: 45678 | C43: S3 | D43: us-west | E43: 72 | F43: 440 | G43: 700 | H43: 630 | I43: Active | J43: =UPPER(TRIM(cloudSense[[#This Row],[service_name]])) -> S3 | K43: =LOWER(TRIM(cloudSense[[#This Row],[region]])) -> us-west | L43: =PROPER(TRIM(cloudSense[[#This Row],[resource_status]])) -> Active | N43: =cloudSense[[#This Row],[allocated_cost]]-cloudSense[[#This Row],[actual_used_cost]] -> 70 | O43: =(cloudSense[[#This Row],[allocated_cost]]-cloudSense[[#This Row],[actual_used_cost]])/cloudSense[[#This Row],[allocated_cost]]*100 -> 10
A44: 43 | B44: 45679 | C44: ec2 | D44: us-east | E44: 11 | F44: 98 | G44: 500 | H44: 110 | I44: Idle | J44: =UPPER(TRIM(cloudSense[[#This Row],[service_name]])) -> EC2 | K44: =LOWER(TRIM(cloudSense[[#This Row],[region]])) -> us-east | L44: =PROPER(TRIM(cloudSense[[#This Row],[resource_status]])) -> Idle | N44: =cloudSense[[#This Row],[allocated_cost]]-cloudSense[[#This Row],[actual_used_cost]] -> 390 | O44: =(cloudSense[[#This Row],[allocated_cost]]-cloudSense[[#This Row],[actual_used_cost]])/cloudSense[[#This Row],[allocated_cost]]*100 -> 78
A45: 44 | B45: 45679 | C45: RDS | D45: eu-central | E45: 58 | F45: 295 | G45: 600 | H45: 505 | I45: Active | J45: =UPPER(TRIM(cloudSense[[#This Row],[service_name]])) -> RDS | K45: =LOWER(TRIM(cloudSense[[#This Row],[region]])) -> eu-central | L45: =PROPER(TRIM(cloudSense[[#This Row],[resource_status]])) -> Active | N45: =cloudSense[[#This Row],[allocated_cost]]-cloudSense[[#This Row],[actual_used_cost]] -> 95 | O45: =(cloudSense[[#This Row],[allocated_cost]]-cloudSense[[#This Row],[actual_used_cost]])/cloudSense[[#This Row],[allocated_cost]]*100 -> 15.833333
A46: 45 | B46: 45680 | C46: Lambda | D46: asia-south | E46: 5 | F46: 20 | G46: 200 | H46: 50 | I46: Idle | J46: =UPPER(TRIM(cloudSense[[#This Row],[service_name]])) -> LAMBDA | K46: =LOWER(TRIM(cloudSense[[#This Row],[region]])) -> asia-south | L46: =PROPER(TRIM(cloudSense[[#This Row],[resource_status]])) -> Idle | N46: =cloudSense[[#This Row],[allocated_cost]]-cloudSense[[#This Row],[actual_used_cost]] -> 150 | O46: =(cloudSense[[#This Row],[allocated_cost]]-cloudSense[[#This Row],[actual_used_cost]])/cloudSense[[#This Row],[allocated_cost]]*100 -> 75
...

Sheet Sheet1

Sheet Cloud_Sense_Clean
A1: record_id | B1: date | C1: storage_gb | D1: allocated_cost | E1: actual_used_cost | F1: service_clean | G1: region_clean | H1: status_clean | I1: waste_cost | J1: waste_percent | K1: cpu_clean
A2: 1 | B2: 45658 | C2: 120 | D2: 500 | E2: 210 | F2: EC2 | G2: us-east | H2: =PROPER(TRIM(cloudSense[[#This Row],[resource_status]])) -> Idle | I2: =cloudSense[[#This Row],[allocated_cost]]-cloudSense[[#This Row],[actual_used_cost]] -> 290 | J2: =((cloudSense[[#This Row],[allocated_cost]]-cloudSense[[#This Row],[actual_used_cost]])/cloudSense[[#This Row],[allocated_cost]]*100)*0.01 -> 0.58 | K2: =IF('cloudSense'!E2="",AVERAGE('cloudSense'!$E$2:$E$201),'cloudSense'!E2) -> 23
A3: 2 | B3: 45658 | C3: 450 | D3: 700 | E3: 690 | F3: S3 | G3: us-west | H3: =PROPER(TRIM(cloudSense[[#This Row],[resource_status]])) -> Active | I3: =cloudSense[[#This Row],[allocated_cost]]-cloudSense[[#This Row],[actual_used_cost]] -> 10 | J3: =((cloudSense[[#This Row],[allocated_cost]]-cloudSense[[#This Row],[actual_used_cost]])/cloudSense[[#This Row],[allocated_cost]]*100)*0.01 -> 0.014285714 | K3: =IF('cloudSense'!E3="",AVERAGE('cloudSense'!$E$2:$E$201),'cloudSense'!E3) -> 78
A4: 3 | B4: 45659 | C4: 90 | D4: 500 | E4: 120 | F4: EC2 | G4: us-east | H4: =PROPER(TRIM(cloudSense[[#This Row],[resource_status]])) -> Idle | I4: =cloudSense[[#This Row],[allocated_cost]]-cloudSense[[#This Row],[actual_used_cost]] -> 380 | J4: =((cloudSense[[#This Row],[allocated_cost]]-cloudSense[[#This Row],[actual_used_cost]])/cloudSense[[#This Row],[allocated_cost]]*100)*0.01 -> 0.76 | K4: =IF('cloudSense'!E4="",AVERAGE('cloudSense'!$E$2:$E$201),'cloudSense'!E4) -> 12
A5: 4 | B5: 45659 | C5: 300 | D5: 600 | E5: 580 | F5: RDS | G5: eu-central | H5: =PROPER(TRIM(cloudSense[[#This Row],[resource_status]])) -> Active | I5: =cloudSense[[#This Row],[allocated_cost]]-cloudSense[[#This Row],[actual_used_cost]] -> 20 | J5: =((cloudSense[[#This Row],[allocated_cost]]-cloudSense[[#This Row],[actual_used_cost]])/cloudSense[[#This Row],[allocated_cost]]*100)*0.01 -> 0.033333333 | K5: =IF('cloudSense'!E5="",AVERAGE('cloudSense'!$E$2:$E$201),'cloudSense'!E5) -> 65
A6: 5 | B6: 45660 | C6: 20 | D6: 200 | E6: 50 | F6: LAMBDA | G6: asia-south | H6: =PROPER(TRIM(cloudSense[[#This Row],[resource_status]])) -> Idle | I6: =cloudSense[[#This Row],[allocated_cost]]-cloudSense[[#This Row],[actual_used_cost]] -> 150 | J6: =((cloudSense[[#This Row],[allocated_cost]]-cloudSense[[#This Row],[actual_used_cost]])/cloudSense[[#This Row],[allocated_cost]]*100)*0.01 -> 0.75 | K6: =IF('cloudSense'!E6="",AVERAGE('cloudSense'!$E$2:$E$201),'cloudSense'!E6) -> 5
A7: 6 | B7: 45660 | C7: 400 | D7: 700 | E7: 650 | F7: S3 | G7: us-west | H7: =PROPER(TRIM(cloudSense[[#This Row],[resource_status]])) -> Active | I7: =cloudSense[[#This Row],[allocated_cost]]-cloudSense[[#This Row],[actual_used_cost]] -> 50 | J7: =((cloudSense[[#This Row],[allocated_cost]]-cloudSense[[#This Row],[actual_used_cost]])/cloudSense[[#This Row],[allocated_cost]]*100)*0.01 -> 0.071428571 | K7: =IF('cloudSense'!E7="",AVERAGE('cloudSense'!$E$2:$E$201),'cloudSense'!E7) -> 47.111111
A8: 7 | B8: 45661 | C8: 150 | D8: 500 | E8: 300 | F8: EC2 | G8: us-east | H8: =PROPER(TRIM(cloudSense[[#This Row],[resource_status]])) -> Active | I8: =cloudSense[[#This Row],[allocated_cost]]-cloudSense[[#This Row],[actual_used_cost]] -> 200 | J8: =((cloudSense[[#This Row],[allocated_cost]]-cloudSense[[#This Row],[actual_used_cost]])/cloudSense[[#This Row],[allocated_cost]]*100)*0.01 -> 0.4 | K8: =IF('cloudSense'!E8="",AVERAGE('cloudSense'!$E$2:$E$201),'cloudSense'!E8) -> 33
A9: 8 | B9: 45661 | C9: 200 | D9: 600 | E9: 150 | F9: RDS | G9: eu-central | H9: =PROPER(TRIM(cloudSense[[#This Row],[resource_status]])) -> Idle | I9: =cloudSense[[#This Row],[allocated_cost]]-cloudSense[[#This Row],[actual_used_cost]] -> 450 | J9: =((cloudSense[[#This Row],[allocated_cost]]-cloudSense[[#This Row],[actual_used_cost]])/cloudSense[[#This Row],[allocated_cost]]*100)*0.01 -> 0.75 | K9: =IF('cloudSense'!E9="",AVERAGE('cloudSense'!$E$2:$E$201),'cloudSense'!E9) -> 18
A10: 9 | B10: 45662 | C10: 250 | D10: 500 | E10: 480 | F10: EC2 | G10: us-east | H10: =PROPER(TRIM(cloudSense[[#This Row],[resource_status]])) -> Active | I10: =cloudSense[[#This Row],[allocated_cost]]-cloudSense[[#This Row],[actual_used_cost]] -> 20 | J10: =((cloudSense[[#This Row],[allocated_cost]]-cloudSense[[#This Row],[actual_used_cost]])/cloudSense[[#This Row],[allocated_cost]]*100)*0.01 -> 0.04 | K10: =IF('cloudSense'!E10="",AVERAGE('cloudSense'!$E$2:$E$201),'cloudSense'!E10) -> 90
A11: 10 | B11: 45662 | C11: 500 | D11: 700 | E11: 400 | F11: S3 | G11: us-west | H11: =PROPER(TRIM(cloudSense[[#This Row],[resource_status]])) -> Active | I11: =cloudSense[[#This Row],[allocated_cost]]-cloudSense[[#This Row],[actual_used_cost]] -> 300 | J11: =((cloudSense[[#This Row],[allocated_cost]]-cloudSense[[#This Row],[actual_used_cost]])/cloudSense[[#This Row],[allocated_cost]]*100)*0.01 -> 0.42857143 | K11: =IF('cloudSense'!E11="",AVERAGE('cloudSense'!$E$2:$E$201),'cloudSense'!E11) -> 45
A12: 11 | B12: 45663 | C12: 80 | D12: 500 | E12: 60 | F12: EC2 | G12: us-east | H12: =PROPER(TRIM(cloudSense[[#This Row],[resource_status]])) -> Idle | I12: =cloudSense[[#This Row],[allocated_cost]]-cloudSense[[#This Row],[actual_used_cost]] -> 440 | J12: =((cloudSense[[#This Row],[allocated_cost]]-cloudSense[[#This Row],[actual_used_cost]])/cloudSense[[#This Row],[allocated_cost]]*100)*0.01 -> 0.88 | K12: =IF('cloudSense'!E12="",AVERAGE('cloudSense'!$E$2:$E$201),'cloudSense'!E12) -> 8
A13: 12 | B13: 45663 | C13: 350 | D13: 600 | E13: 590 | F13: RDS | G13: asia-south | H13: =PROPER(TRIM(cloudSense[[#This Row],[resource_status]])) -> Active | I13: =cloudSense[[#This Row],[allocated_cost]]-cloudSense[[#This Row],[actual_used_cost]] -> 10 | J13: =((cloudSense[[#This Row],[allocated_cost]]-cloudSense[[#This Row],[actual_used_cost]])/cloudSense[[#This Row],[allocated_cost]]*100)*0.01 -> 0.016666667 | K13: =IF('cloudSense'!E13="",AVERAGE('cloudSense'!$E$2:$E$201),'cloudSense'!E13) -> 72
... A201: 200 | B201: 45757 | C201: 335 | D201: 600 | E201: 595 | F201: RDS | G201: eu-central | H201: =PROPER(TRIM(cloudSense[[#This Row],[resource_status]])) -> Active | I201: =cloudSense[[#This Row],[allocated_cost]]-cloudSense[[#This Row],[actual_used_cost]] -> 5 | J201: =((cloudSense[[#This Row],[allocated_cost]]-cloudSense[[#This Row],[actual_used_cost]])/cloudSense[[#This Row],[allocated_cost]]*100)*0.01 -> 0.0083333333 | K201: =IF('cloudSense'!E201="",AVERAGE('cloudSense'!$E$2:$E$201),'cloudSense'!E201) -> 78
